Workbook

Sheet Final
B1: NEED | D1: Requirement Description | H1: Requirement Info | L1: Functional
A2: Old ID | B2: Relevant Need(s) | D2: Req ID | E2: Requirement Name | F2: Requirement Statement | H2: Category | I2: Type | J2: Verification Method | L2: Function | M2: Function Rational | N2: Lower Functional | O2: Reason
A3: 1 | B3: N1 | D3: ANGARS-1 | E3: Autonomous Refueling | F3: The system shall execute autonomous refueling via onboard sensors without human assistance. | H3: Operational | I3: Binary | J3: Demonstration | L3: =VLOOKUP(D3,VLOOKUP!A:D,2,FALSE) -> F2: Control Autonomous Docking_THIS F3: Execute Fuel Transfer_THIS | M3: =VLOOKUP(D3,VLOOKUP!A:D,3,FALSE) -> F2 (autonomous docking) and F3 (fuel transfer) enable refueling without human intervention. | N3: =VLOOKUP(Final!D3,'Satisfied By'!A:E,4,FALSE) -> F3.3: Initiate Fuel Transfer | O3: =VLOOKUP(Final!D3,'Satisfied By'!A:E,5,FALSE) -> This activity autonomously starts the fuel transfer process based on sensor inputs, ensuring that refueling proceeds without human intervention.
A4: 6 | B4: N1 | D4: ANGARS-2 | E4: Refueling Time | F4: The system shall complete refueling within 10 minutes (T), 8 minutes (O) of handshake (alignment) with receiving aircraft. | H4: Operational | I4: Quantitative | J4: Test | L4: =VLOOKUP(D4,VLOOKUP!A:D,2,FALSE) -> None | M4: =VLOOKUP(D4,VLOOKUP!A:D,3,FALSE) -> Refueling time is a performance metric not captured in functional flows. | N4: =VLOOKUP(Final!D4,'Satisfied By'!A:E,4,FALSE) -> F3.6: Complete Transfer | O4: =VLOOKUP(Final!D4,'Satisfied By'!A:E,5,FALSE) -> This L3 behavior marks the completion of fuel transfer and serves as the time-reference point to verify that the overall process meets the specified duration. (Note: Timing is managed through performance monitoring at the system level.)
A5: 9 | B5: N1 | D5: ANGARS-3 | E5: Proximity Safety Abort | F5: The system shall abort refueling if the receiving aircraft proximity exits established safe bounds. | H5: Operational | I5: Binary | J5: Test | L5: =VLOOKUP(D5,VLOOKUP!A:D,2,FALSE) -> F4: Monitor Safety & Diagnostics_THIS | M5: =VLOOKUP(D5,VLOOKUP!A:D,3,FALSE) -> F4 monitors proximity and triggers safety abort via alerts to F2/F3. | N5: =VLOOKUP(Final!D5,'Satisfied By'!A:E,4,FALSE) -> F4.1: Monitor Proximity | O5: =VLOOKUP(Final!D5,'Satisfied By'!A:E,5,FALSE) -> This behavior continuously checks aircraft proximity and triggers an abort when limits are exceeded, directly meeting the safety abort requirement.
A6: 13 | B6: N1 | D6: ANGARS-4 | E6: Aircraft ID Verification | F6: The system shall verify and validate receiving aircraft identity before beginning fuel transfer. | H6: Operational | I6: Binary | J6: Demonstration | L6: =VLOOKUP(D6,VLOOKUP!A:D,2,FALSE) -> F1: Manage Refueling Requests_THIS | M6: =VLOOKUP(D6,VLOOKUP!A:D,3,FALSE) -> F1 verifies aircraft identity during refueling request processing. | N6: =VLOOKUP(Final!D6,'Satisfied By'!A:E,4,FALSE) -> F1.1: Receive & Authenticate Request | O6: =VLOOKUP(Final!D6,'Satisfied By'!A:E,5,FALSE) -> This activity accepts and authenticates refueling requests—including aircraft identity verification—before fuel transfer commences.
A7: 16 | B7: N1 | D7: ANGARS-5 | E7: Turbulence Stability | F7: The system shall maintain a stable connection with the receiving aircraft during turbulence. | H7: Operational | I7: Binary | J7: Test | L7: =VLOOKUP(D7,VLOOKUP!A:D,2,FALSE) -> F2: Control Autonomous Docking_THIS | M7: =VLOOKUP(D7,VLOOKUP!A:D,3,FALSE) -> F2 stabilizes the connection during turbulence using guidance signals from F6. | N7: =VLOOKUP(Final!D7,'Satisfied By'!A:E,4,FALSE) -> F2.5: Stabilize During Turbulence | O7: =VLOOKUP(Final!D7,'Satisfied By'!A:E,5,FALSE) -> This L3 behavior adjusts control parameters to maintain a stable connection during turbulent conditions.
A8: 19 | B8: N1 | D8: ANGARS-6 | E8: Probe Alignment Accuracy | F8: The system shall align the refueling probe within 0.5m (T), 0.25m (O) of the receiving aircrafts fueling port. | H8: Operational | I8: Quantitative | J8: Test | L8: =VLOOKUP(D8,VLOOKUP!A:D,2,FALSE) -> F2: Control Autonomous Docking_THIS | M8: =VLOOKUP(D8,VLOOKUP!A:D,3,FALSE) -> F2 aligns the probe within accuracy bounds using F6’s navigation signals. | N8: =VLOOKUP(Final!D8,'Satisfied By'!A:E,4,FALSE) -> F2.4: Align Refueling Probe | O8: =VLOOKUP(Final!D8,'Satisfied By'!A:E,5,FALSE) -> This behavior uses sensor data to achieve the required alignment accuracy between the probe and the fueling port.
A9: 22 | B9: N1 | D9: ANGARS-7 | E9: Fuel Leak Detection | F9: The system shall detect fuel leaks and cease fuel transfers immediately. | H9: Operational | I9: Binary | J9: Test | L9: =VLOOKUP(D9,VLOOKUP!A:D,2,FALSE) -> F3: Execute Fuel Transfer_THIS F4: Monitor Safety & Diagnostics_THIS | M9: =VLOOKUP(D9,VLOOKUP!A:D,3,FALSE) -> F3 detects leaks and stops transfer; F4 logs diagnostics. | N9: =VLOOKUP(Final!D9,'Satisfied By'!A:E,4,FALSE) -> F3.5: Emergency Shutdown | O9: =VLOOKUP(Final!D9,'Satisfied By'!A:E,5,FALSE) -> This activity halts fuel transfer immediately upon leak detection, thereby ensuring safety.
A10: 25 | B10: N1 | D10: ANGARS-8 | E10: Adaptive Fuel Speed | F10: The system shall adjust refueling speed based on receiving aircraft stability. | H10: Operational | I10: Qualitative | J10: Analysis | L10: =VLOOKUP(D10,VLOOKUP!A:D,2,FALSE) -> F3: Execute Fuel Transfer_THIS | M10: =VLOOKUP(D10,VLOOKUP!A:D,3,FALSE) -> F3 adjusts fuel speed based on stability data from F2. | N10: =VLOOKUP(Final!D10,'Satisfied By'!A:E,4,FALSE) -> F3.7: Adjust Flow Rate | O10: =VLOOKUP(Final!D10,'Satisfied By'!A:E,5,FALSE) -> This L3 behavior dynamically modifies fuel flow in response to aircraft stability data.
A11: 28 | B11: N1 | D11: ANGARS-9 | E11: Probe Retraction | F11: The system shall retract the refueling probe when refueling has completed | H11: Operational | I11: Binary | J11: Demonstration | L11: =VLOOKUP(D11,VLOOKUP!A:D,2,FALSE) -> F2: Control Autonomous Docking_THIS | M11: =VLOOKUP(D11,VLOOKUP!A:D,3,FALSE) -> F2 retracts the probe after F3 confirms fuel transfer completion. | N11: =VLOOKUP(Final!D11,'Satisfied By'!A:E,4,FALSE) -> F2.6: Retract Probe | O11: =VLOOKUP(Final!D11,'Satisfied By'!A:E,5,FALSE) -> This activity manages the safe retraction of the probe immediately after transfer completion.
A12: 2 | B12: N1, N2 | D12: ANGARS-10 | E12: Multi-Platform Refueling | F12: The system shall employ refueling procedures for both manned and unmanned aircraft. | H12: Operational | I12: Qualitative | J12: Test | L12: =VLOOKUP(D12,VLOOKUP!A:D,2,FALSE) -> F1: Manage Refueling Requests_THIS | M12: =VLOOKUP(D12,VLOOKUP!A:D,3,FALSE) -> F1 handles refueling requests for both manned and unmanned aircraft. | N12: =VLOOKUP(Final!D12,'Satisfied By'!A:E,4,FALSE) -> F1.1: Receive & Authenticate Request | O12: =VLOOKUP(Final!D12,'Satisfied By'!A:E,5,FALSE) -> By processing refueling requests from all aircraft types, this activity ensures that procedures are applied uniformly for both manned and unmanned platforms.
A13: 31 | B13: N2 | D13: ANGARS-11 | E13: Wingspan Compatibility | F13: The system shall support refueling for autonomous aircraft with wingspans of 5m-15m (T), 5m-18m (O). | H13: Functional | I13: Binary | J13: Test | L13: =VLOOKUP(D13,VLOOKUP!A:D,2,FALSE) -> F2: Control Autonomous Docking_THIS | M13: =VLOOKUP(D13,VLOOKUP!A:D,3,FALSE) -> F2 adjusts docking procedures for wingspan compatibility. | N13: =VLOOKUP(Final!D13,'Satisfied By'!A:E,4,FALSE) -> F2.2: Adjust Boom Length & Altitude | O13: =VLOOKUP(Final!D13,'Satisfied By'!A:E,5,FALSE) -> This behavior adjusts the docking mechanism to account for different aircraft dimensions—including wingspan—ensuring compatibility.
A14: 32 | B14: N2 | D14: ANGARS-12 | E14: Fuel Flow Adaptation | F14: The system shall adjust fuel flow rate based on receiving aircraft type and properties. | H14: Functional | I14: Qualitative | J14: Demonstration | L14: =VLOOKUP(D14,VLOOKUP!A:D,2,FALSE) -> F3: Execute Fuel Transfer_THIS | M14: =VLOOKUP(D14,VLOOKUP!A:D,3,FALSE) -> F3 adapts fuel flow rate based on aircraft type/properties. | N14: =VLOOKUP(Final!D14,'Satisfied By'!A:E,4,FALSE) -> F3.7: Adjust Flow Rate | O14: =VLOOKUP(Final!D14,'Satisfied By'!A:E,5,FALSE) -> This L3 activity modulates fuel flow according to aircraft-specific parameters to optimize the transfer process.
... A30: 29 | B30: N3 | D30: ANGARS-28 | E30: Threat Zone Avoidance | F30: The system shall automatically reroute missions to avoid known threat zones. | H30: Operational | I30: Qualitative | J30: Analysis | L30: =VLOOKUP(D30,VLOOKUP!A:D,2,FALSE) -> F6: Operate in Adverse Conditions_THIS | M30: =VLOOKUP(D30,VLOOKUP!A:D,3,FALSE) -> F6 reroutes missions to avoid threat zones. | N30: =VLOOKUP(Final!D30,'Satisfied By'!A:E,4,FALSE) -> F6: Operate in Adverse Conditions (L2) | O30: =VLOOKUP(Final!D30,'Satisfied By'!A:E,5,FALSE) -> The overall function assesses threat zones and dynamically adjusts mission routes to avoid high-risk areas.
A31: R169 | B31: N3 | D31: ANGARS-29 | E31: Satellite Relay | F31: The system shall reroute mission data through relay satellites if direct ground links are jammed. | H31: Operational | I31: Binary | J31: Test | L31: =VLOOKUP(D31,VLOOKUP!A:D,2,FALSE) -> F5: Manage Communications_THIS | M31: =VLOOKUP(D31,VLOOKUP!A:D,3,FALSE) -> F5 reroutes data through relay satellites (RS) during jamming. | N31: =VLOOKUP(Final!D31,'Satisfied By'!A:E,4,FALSE) -> F5: Manage Communications (L2) | O31: =VLOOKUP(Final!D31,'Satisfied By'!A:E,5,FALSE) -> The communications function includes the ability to reroute data via relay satellites when direct links are compromised.
A32: 92 | B32: N4 | D32: ANGARS-30 | E32: Pre-Comm Authentication | F32: The system shall authenticate all receiving aircraft before data exchange. | H32: External Interface | I32: Binary | J32: Test | L32: =VLOOKUP(D32,VLOOKUP!A:D,2,FALSE) -> F7: Enforce Cybersecurity_THIS | M32: =VLOOKUP(D32,VLOOKUP!A:D,3,FALSE) -> F7 authenticates receiving aircraft before data exchange. | N32: =VLOOKUP(Final!D32,'Satisfied By'!A:E,4,FALSE) -> F7.2: Authenticate Aircraft | O32: =VLOOKUP(Final!D32,'Satisfied By'!A:E,5,FALSE) -> This activity ensures that only authenticated aircraft are permitted to exchange data, meeting the pre-communication security requirement.
A33: 94 | B33: N4 | D33: ANGARS-31 | E33: Low-Latency Commands | F33: The system shall maintain ≤ 15ms (T), 10ms (O) latency in command transmission. | H33: External Interface | I33: Quantitative | J33: Test | L33: =VLOOKUP(D33,VLOOKUP!A:D,2,FALSE) -> F5: Manage Communications_THIS | M33: =VLOOKUP(D33,VLOOKUP!A:D,3,FALSE) -> F5 ensures low-latency command transmission. | N33: =VLOOKUP(Final!D33,'Satisfied By'!A:E,4,FALSE) -> F5.4: Send Data | O33: =VLOOKUP(Final!D33,'Satisfied By'!A:E,5,FALSE) -> This L3 behavior is responsible for transmitting commands with minimal delay, ensuring that the low-latency requirement is achieved.
A34: 97 | B34: N4 | D34: ANGARS-32 | E34: Anti-Jamming Hopping | F34: The system shall employ frequency-hopping techniques to counter jamming attempts. | H34: External Interface | I34: Binary | J34: Test | L34: =VLOOKUP(D34,VLOOKUP!A:D,2,FALSE) -> F5: Manage Communications_THIS | M34: =VLOOKUP(D34,VLOOKUP!A:D,3,FALSE) -> F5 employs frequency-hopping to counter jamming. | N34: =VLOOKUP(Final!D34,'Satisfied By'!A:E,4,FALSE) -> F5.5: Activate Comms Countermeasures | O34: =VLOOKUP(Final!D34,'Satisfied By'!A:E,5,FALSE) -> This behavior activates techniques (including frequency hopping) to mitigate jamming and maintain robust communications.
A35: 99 | B35: N4 | D35: ANGARS-33 | E35: Communication Uptime | F35: The system shall sustain communication uptime of ≥ 99.8% (T), 99.9% (O) between receiving aircraft. | H35: External Interface | I35: Quantitative | J35: Analysis | L35: =VLOOKUP(D35,VLOOKUP!A:D,2,FALSE) -> F5: Manage Communications_THIS | M35: =VLOOKUP(D35,VLOOKUP!A:D,3,FALSE) -> F5 sustains communication uptime. | N35: =VLOOKUP(Final!D35,'Satisfied By'!A:E,4,FALSE) -> F5: Manage Communications (L2) | O35: =VLOOKUP(Final!D35,'Satisfied By'!A:E,5,FALSE) -> The overall communications function is engineered for high availability and continuous connectivity.
A36: 103 | B36: N4 | D36: ANGARS-34 | E36: Data Loss Limit | F36: The system shall have data packet loss of ≤ 0.2% (T), 0.1% (O). | H36: External Interface | I36: Quantitative | J36: Test | L36: =VLOOKUP(D36,VLOOKUP!A:D,2,FALSE) -> F5: Manage Communications_THIS | M36: =VLOOKUP(D36,VLOOKUP!A:D,3,FALSE) -> F5 limits data packet loss. | N36: =VLOOKUP(Final!D36,'Satisfied By'!A:E,4,FALSE) -> F5: Manage Communications (L2) | O36: =VLOOKUP(Final!D36,'Satisfied By'!A:E,5,FALSE) -> This function is designed to maintain high data integrity, ensuring packet loss remains within prescribed limits.
A37: 105 | B37: N4 | D37: ANGARS-35 | E37: Unauthorized Connection Termination | F37: The system shall terminate unauthenticated connections. | H37: External Interface | I37: Binary | J37: Test | L37: =VLOOKUP(D37,VLOOKUP!A:D,2,FALSE) -> F7: Enforce Cybersecurity_THIS | M37: =VLOOKUP(D37,VLOOKUP!A:D,3,FALSE) -> F7 terminates unauthenticated connections. | N37: =VLOOKUP(Final!D37,'Satisfied By'!A:E,4,FALSE) -> F7.3: Terminate Unauthorized Connections | O37: =VLOOKUP(Final!D37,'Satisfied By'!A:E,5,FALSE) -> This activity actively disconnects any connection that fails authentication, thereby securing the network.
A38: 107 | B38: N4 | D38: ANGARS-36 | E38: RF Masking | F38: The system shall employ RF signature masking techniques during covert operations. | H38: External Interface | I38: Qualitative | J38: Analysis | L38: =VLOOKUP(D38,VLOOKUP!A:D,2,FALSE) -> F7: Enforce Cybersecurity_THIS | M38: =VLOOKUP(D38,VLOOKUP!A:D,3,FALSE) -> F7 employs RF masking during covert operations. | N38: =VLOOKUP(Final!D38,'Satisfied By'!A:E,4,FALSE) -> F7.4: Zero-Trust & RF Masking | O38: =VLOOKUP(Final!D38,'Satisfied By'!A:E,5,FALSE) -> This behavior implements RF masking to obscure the system’s signature, supporting covert operations.
A39: 109 | B39: N4 | D39: ANGARS-37 | E39: Certificate Validation | F39: The system shall validate digital certificates for all receiving aircrafts. | H39: External Interface | I39: Binary | J39: Test | L39: =VLOOKUP(D39,VLOOKUP!A:D,2,FALSE) -> F7: Enforce Cybersecurity_THIS | M39: =VLOOKUP(D39,VLOOKUP!A:D,3,FALSE) -> F7 validates digital certificates. | N39: =VLOOKUP(Final!D39,'Satisfied By'!A:E,4,FALSE) -> F7.1: Validate Digital Certificates | O39: =VLOOKUP(Final!D39,'Satisfied By'!A:E,5,FALSE) -> This L3 activity rigorously checks digital certificates to ensure only trusted entities communicate with the system.
A40: 111 | B40: N4 | D40: ANGARS-38 | E40: Message Integrity During Jamming | F40: The system shall achieve ≥ 98% (T), 99% (O) message integrity during jamming. | H40: External Interface | I40: Quantitative | J40: Test | L40: =VLOOKUP(D40,VLOOKUP!A:D,2,FALSE) -> F7: Enforce Cybersecurity_THIS | M40: =VLOOKUP(D40,VLOOKUP!A:D,3,FALSE) -> F7 ensures message integrity during jamming. | N40: =VLOOKUP(Final!D40,'Satisfied By'!A:E,4,FALSE) -> F7.6: Ensure Msg Integrity | O40: =VLOOKUP(Final!D40,'Satisfied By'!A:E,5,FALSE) -> This behavior monitors and preserves the integrity of messages during jamming conditions, meeting the high-integrity threshold.
A41: 113 | B41: N4 | D41: ANGARS-39 | E41: Zero-Trust Network | F41: The system shall implement a zero-trust network architecture, verifying all access requests regardless of origin. | H41: External Interface | I41: Qualitative | J41: Analysis | L41: =VLOOKUP(D41,VLOOKUP!A:D,2,FALSE) -> F7: Enforce Cybersecurity_THIS | M41: =VLOOKUP(D41,VLOOKUP!A:D,3,FALSE) -> F7 implements zero-trust network architecture. | N41: =VLOOKUP(Final!D41,'Satisfied By'!A:E,4,FALSE) -> F7.4: Zero-Trust & RF Masking | O41: =VLOOKUP(Final!D41,'Satisfied By'!A:E,5,FALSE) -> By enforcing a zero-trust model, this activity ensures that every access request is verified before communication is allowed.
A42: 115 | B42: N4 | D42: ANGARS-40 | E42: Encryption Recovery | F42: The system shall re-establish encrypted communication within 5 seconds (T), 4 seconds (O) of signal loss. | H42: External Interface | I42: Quantitative | J42: Test | L42: =VLOOKUP(D42,VLOOKUP!A:D,2,FALSE) -> F7: Enforce Cybersecurity_THIS | M42: =VLOOKUP(D42,VLOOKUP!A:D,3,FALSE) -> F7 re-establishes encryption after signal loss. | N42: =VLOOKUP(Final!D42,'Satisfied By'!A:E,4,FALSE) -> F7.7: Re-establish Encryption | O42: =VLOOKUP(Final!D42,'Satisfied By'!A:E,5,FALSE) -> This L3 behavior rapidly restores encryption after any signal loss, ensuring continuous secure communications.
A43: 117 | B43: N4 | D43: ANGARS-41 | E43: Tampered Data Erase | F43: The system shall erase sensitive data and notify ground control if tampering is detected. | H43: External Interface | I43: Binary | J43: Demonstration | L43: =VLOOKUP(D43,VLOOKUP!A:D,2,FALSE) -> F7: Enforce Cybersecurity_THIS | M43: =VLOOKUP(D43,VLOOKUP!A:D,3,FALSE) -> F7 erases tampered data and notifies ground control. | N43: =VLOOKUP(Final!D43,'Satisfied By'!A:E,4,FALSE) -> F7.8: Erase Data if Tampered | O43: =VLOOKUP(Final!D43,'Satisfied By'!A:E,5,FALSE) -> This activity immediately erases sensitive data upon detecting tampering and sends an alert to ground control.
... A96: 90 | B96: N10 | D96: ANGARS-94 | E96: Countermeasure Updates | F96: The system shall update countermeasure protocols via over-the-air (OTA) updates within 24 hours (T), 12 hours (O) of new threat identification | H96: Performance | I96: Quantitative | J96: Analysis | L96: =VLOOKUP(D96,VLOOKUP!A:D,2,FALSE) -> #N/A | M96: =VLOOKUP(D96,VLOOKUP!A:D,3,FALSE) -> #N/A | N96: =VLOOKUP(Final!D96,'Satisfied By'!A:E,4,FALSE) -> F5.4: Send Data | O96: =VLOOKUP(Final!D96,'Satisfied By'!A:E,5,FALSE) -> This behavior supports the rapid transmission of countermeasure updates in response to new threats.
A97: R170 | B97: N10 | D97: ANGARS-95 | E97: Threat Alert Priority | F97: The system shall prioritize threat alerts over non-critical communications during contested operations. | H97: Performance | I97: Qualitative | J97: Analysis | L97: =VLOOKUP(D97,VLOOKUP!A:D,2,FALSE) -> #N/A | M97: =VLOOKUP(D97,VLOOKUP!A:D,3,FALSE) -> #N/A | N97: =VLOOKUP(Final!D97,'Satisfied By'!A:E,4,FALSE) -> F6.5: Send Status | O97: =VLOOKUP(Final!D97,'Satisfied By'!A:E,5,FALSE) -> This activity ensures that threat alerts are prioritized and communicated in real-time during operational disruptions.
A98: 126 | B98: N11 | D98: ANGARS-96 | E98: Annual Autonomy Testing | F98: The system shall meet all requirements of the autonomous mode test protocols each year. | H98: Constraint | I98: Binary | J98: Test | L98: =VLOOKUP(D98,VLOOKUP!A:D,2,FALSE) -> #N/A | M98: =VLOOKUP(D98,VLOOKUP!A:D,3,FALSE) -> #N/A | N98: =VLOOKUP(Final!D98,'Satisfied By'!A:E,4,FALSE) -> N/A – This is verified through annual testing and certification processes. | O98: =VLOOKUP(Final!D98,'Satisfied By'!A:E,5,FALSE) -> Autonomous systems are regularly tested against defined protocols to ensure compliance.
A99: 129 | B99: N11 | D99: ANGARS-97 | E99: Sensor Accuracy Validation | F99: The system shall validate sensor accuracy during testing to ±1% (T), ±0.5% (O) during testing. | H99: Constraint | I99: Quantitative | J99: Test | L99: =VLOOKUP(D99,VLOOKUP!A:D,2,FALSE) -> #N/A | M99: =VLOOKUP(D99,VLOOKUP!A:D,3,FALSE) -> #N/A | N99: =VLOOKUP(Final!D99,'Satisfied By'!A:E,4,FALSE) -> N/A – Sensor accuracy is validated through calibration processes. | O99: =VLOOKUP(Final!D99,'Satisfied By'!A:E,5,FALSE) -> Sensor accuracy is checked and validated as part of system integration testing.
A100: 134 | B100: N11 | D100: ANGARS-98 | E100: Sandbox Software Testing | F100: The system shall validate all software updates in a sandbox environment before flight implementation. | H100: Constraint | I100: Binary | J100: Test | L100: =VLOOKUP(D100,VLOOKUP!A:D,2,FALSE) -> #N/A | M100: =VLOOKUP(D100,VLOOKUP!A:D,3,FALSE) -> #N/A | N100: =VLOOKUP(Final!D100,'Satisfied By'!A:E,4,FALSE) -> N/A – Software updates are tested in a sandbox environment during development. | O100: =VLOOKUP(Final!D100,'Satisfied By'!A:E,5,FALSE) -> This is verified as part of software development lifecycle testing.
A101: 138 | B101: N11 | D101: ANGARS-99 | E101: Algorithm Test Coverage | F101: The system shall ensure that all autonomous algorithms are thoroughly tested, achieving 98% (T), 100% (O) test coverage for autonomous algorithms against DO-178C standards and regulations. | H101: Constraint | I101: Quantitative | J101: Analysis | L101: =VLOOKUP(D101,VLOOKUP!A:D,2,FALSE) -> #N/A | M101: =VLOOKUP(D101,VLOOKUP!A:D,3,FALSE) -> #N/A | N101: =VLOOKUP(Final!D101,'Satisfied By'!A:E,4,FALSE) -> N/A – Algorithm coverage is verified through comprehensive testing of software modules. | O101: =VLOOKUP(Final!D101,'Satisfied By'!A:E,5,FALSE) -> Verified through testing protocols for autonomous software, ensuring compliance with DO-178C.
A102: 142 | B102: N11 | D102: ANGARS-100 | E102: Sensor Calibration | F102: The system shall calibrate sensors to 0.5% (T), 0.25% (O) error margin semi-annually. | H102: Constraint | I102: Quantitative | J102: Demonstration | L102: =VLOOKUP(D102,VLOOKUP!A:D,2,FALSE) -> #N/A | M102: =VLOOKUP(D102,VLOOKUP!A:D,3,FALSE) -> #N/A | N102: =VLOOKUP(Final!D102,'Satisfied By'!A:E,4,FALSE) -> N/A – Sensor calibration is part of the system maintenance process and not represented by an individual L3 activity. | O102: =VLOOKUP(Final!D102,'Satisfied By'!A:E,5,FALSE) -> This is verified through periodic system-level checks and calibration processes.
A103: 146 | B103: N11 | D103: ANGARS-101 | E103: Software Checksum | F103: The system shall verify software integrity via checksum check pre-deployment. | H103: Constraint | I103: Binary | J103: Inspection | L103: =VLOOKUP(D103,VLOOKUP!A:D,2,FALSE) -> #N/A | M103: =VLOOKUP(D103,VLOOKUP!A:D,3,FALSE) -> #N/A | N103: =VLOOKUP(Final!D103,'Satisfied By'!A:E,4,FALSE) -> N/A – Software integrity is verified through pre-deployment verification processes. | O103: =VLOOKUP(Final!D103,'Satisfied By'!A:E,5,FALSE) -> This is verified through checksum comparison as part of software deployment procedures.
A104: 150 | B104: N11 | D104: ANGARS-102 | E104: Hardware Durability Testing | F104: The system shall validate hardware durability over 8,000 (T) operational hours, 10,000 (O) operational hours. | H104: Constraint | I104: Quantitative | J104: Test | L104: =VLOOKUP(D104,VLOOKUP!A:D,2,FALSE) -> #N/A | M104: =VLOOKUP(D104,VLOOKUP!A:D,3,FALSE) -> #N/A | N104: =VLOOKUP(Final!D104,'Satisfied By'!A:E,4,FALSE) -> N/A – Hardware durability testing is part of the system qualification process and not a discrete L3 function. | O104: =VLOOKUP(Final!D104,'Satisfied By'!A:E,5,FALSE) -> Confirmed through hardware qualification testing to ensure it meets required operational hours.
A105: 34 | B105: N12 | D105: ANGARS-103 | E105: HMI Mission Display | F105: The HMI shall display real-time mission schedules, queued aircraft status, and threat alerts for operators. | H105: Functional | I105: Qualitative | J105: Demonstration | L105: =VLOOKUP(D105,VLOOKUP!A:D,2,FALSE) -> F8: Manage HMI_THIS | M105: =VLOOKUP(D105,VLOOKUP!A:D,3,FALSE) -> F8 displays real-time mission schedules and threat alerts. | N105: =VLOOKUP(Final!D105,'Satisfied By'!A:E,4,FALSE) -> F8.1: Display Mission Data | O105: =VLOOKUP(Final!D105,'Satisfied By'!A:E,5,FALSE) -> This behavior ensures that the HMI displays mission schedules and updates to operators, meeting the real-time display requirement.
A106: 37 | B106: N12 | D106: ANGARS-104 | E106: Manual Override Speed | F106: The HMI shall allow manual override within 2.5 seconds (T), 2 seconds (O). | H106: Functional | I106: Quantitative | J106: Demonstration | L106: =VLOOKUP(D106,VLOOKUP!A:D,2,FALSE) -> F8: Manage HMI_THIS | M106: =VLOOKUP(D106,VLOOKUP!A:D,3,FALSE) -> F8 allows manual override within required speed. | N106: =VLOOKUP(Final!D106,'Satisfied By'!A:E,4,FALSE) -> F8.3: Process Manual Override | O106: =VLOOKUP(Final!D106,'Satisfied By'!A:E,5,FALSE) -> This activity ensures that manual override commands are processed within the required timeframes.
A107: 40 | B107: N12 | D107: ANGARS-105 | E107: Emergency Shutdown | F107: The HMI shall include emergency shutdown controls. | H107: Functional | I107: Binary | J107: Test | L107: =VLOOKUP(D107,VLOOKUP!A:D,2,FALSE) -> F8: Manage HMI_THIS | M107: =VLOOKUP(D107,VLOOKUP!A:D,3,FALSE) -> F8 includes emergency shutdown controls. | N107: =VLOOKUP(Final!D107,'Satisfied By'!A:E,4,FALSE) -> F8.4: Execute Emergency Controls | O107: =VLOOKUP(Final!D107,'Satisfied By'!A:E,5,FALSE) -> This behavior includes an emergency shutdown process, ensuring operators can quickly disable systems in case of an emergency.
...

Sheet Satisfied By
A1: Req ID | B1: Requirement Name | C1: Requirement Statement | D1: Activity Name | E1: Reason
A2: ANGARS-1 | B2: Autonomous Refueling | C2: The system shall execute autonomous refueling via onboard sensors without human assistance. | D2: F3.3: Initiate Fuel Transfer | E2: This activity autonomously starts the fuel transfer process based on sensor inputs, ensuring that refueling proceeds without human intervention.
A3: ANGARS-2 | B3: Refueling Time | C3: The system shall complete refueling within 10 minutes (T), 8 minutes (O) of handshake (alignment) with receiving aircraft. | D3: F3.6: Complete Transfer | E3: This L3 behavior marks the completion of fuel transfer and serves as the time-reference point to verify that the overall process meets the specified duration. (Note: Timing is managed through performance monitoring at the system level.)
A4: ANGARS-3 | B4: Proximity Safety Abort | C4: The system shall abort refueling if the receiving aircraft proximity exits established safe bounds. | D4: F4.1: Monitor Proximity | E4: This behavior continuously checks aircraft proximity and triggers an abort when limits are exceeded, directly meeting the safety abort requirement.
A5: ANGARS-4 | B5: Aircraft ID Verification | C5: The system shall verify and validate receiving aircraft identity before beginning fuel transfer. | D5: F1.1: Receive & Authenticate Request | E5: This activity accepts and authenticates refueling requests—including aircraft identity verification—before fuel transfer commences.
A6: ANGARS-5 | B6: Turbulence Stability | C6: The system shall maintain a stable connection with the receiving aircraft during turbulence. | D6: F2.5: Stabilize During Turbulence | E6: This L3 behavior adjusts control parameters to maintain a stable connection during turbulent conditions.
A7: ANGARS-6 | B7: Probe Alignment Accuracy | C7: The system shall align the refueling probe within 0.5m (T), 0.25m (O) of the receiving aircrafts fueling port. | D7: F2.4: Align Refueling Probe | E7: This behavior uses sensor data to achieve the required alignment accuracy between the probe and the fueling port.
A8: ANGARS-7 | B8: Fuel Leak Detection | C8: The system shall detect fuel leaks and cease fuel transfers immediately. | D8: F3.5: Emergency Shutdown | E8: This activity halts fuel transfer immediately upon leak detection, thereby ensuring safety.
A9: ANGARS-8 | B9: Adaptive Fuel Speed | C9: The system shall adjust refueling speed based on receiving aircraft stability. | D9: F3.7: Adjust Flow Rate | E9: This L3 behavior dynamically modifies fuel flow in response to aircraft stability data.
A10: ANGARS-9 | B10: Probe Retraction | C10: The system shall retract the refueling probe when refueling has completed | D10: F2.6: Retract Probe | E10: This activity manages the safe retraction of the probe immediately after transfer completion.
A11: ANGARS-10 | B11: Multi-Platform Refueling | C11: The system shall employ refueling procedures for both manned and unmanned aircraft. | D11: F1.1: Receive & Authenticate Request | E11: By processing refueling requests from all aircraft types, this activity ensures that procedures are applied uniformly for both manned and unmanned platforms.
A12: ANGARS-11 | B12: Wingspan Compatibility | C12: The system shall support refueling for autonomous aircraft with wingspans of 5m-15m (T), 5m-18m (O). | D12: F2.2: Adjust Boom Length & Altitude | E12: This behavior adjusts the docking mechanism to account for different aircraft dimensions—including wingspan—ensuring compatibility.
... A66: ANGARS-65 | B66: Mission Abort Limit | C66: The system shall limit mission aborts caused by subsystem failures to ≤ 3% (T), 2% (O). | D66: F4: Monitor Safety & Diagnostics (L2) | E66: The integrated safety function is designed to minimize false aborts through robust diagnostic checks.
A67: ANGARS-66 | B67: Data Archival | C67: The system shall archive mission data for ≥ 30 days (T), 45 days post-operation. | D67: F4.3: Log Failures and Archive Data – This behavior archives mission and diagnostic data for the required retention period.
A68: ANGARS-67 | B68: Post-Mission Reports | C68: The system shall generate post-mission performance reports. | D68: F1.6: Transmit Status & Reports – This activity compiles and sends detailed post-mission reports, thereby satisfying the reporting requirement.
A69: ANGARS-68 | B69: Status Notifications | C69: The system shall notify operators of mission success/failure within 1 minute (T), 30 seconds (O). | D69: F4.6: Send Status Notifications | E69: This behavior sends status notifications to operators in real-time, ensuring timely updates on mission success or failure.
A70: ANGARS-69 | B70: False Abort Limit | C70: The system shall limit false-positive mission aborts to no more than 2% (T), 1% (O). | D70: F4.6: Send Status Notifications | E70: This behavior helps to minimize false mission aborts by accurately logging and notifying operators about the mission status.
A71: ANGARS-70 | B71: Fuel Compatibility Check | C71: The system shall validate fuel compatibility between receiving aircraft before transfer. | D71: F3.1: Validate Fuel Compatibility | E71: This activity ensures that only compatible fuel types are used, validating the compatibility of the fuel before the transfer begins.
A72: ANGARS-71 | B72: Pump Fault Detection | C72: The system shall detect faults in fuel pumps within 5 seconds (T), 2 seconds (O). | D72: N/A – Fault detection is part of the integrated diagnostic system and not covered by an individual L3 behavior. | E72: Fault detection is part of the overall system functionality for monitoring and preventing pump failures.
A73: ANGARS-72 | B73: Predictive Pump Analysis | C73: The system shall implement algorithms to predict pump failures using vibrational analysis. | D73: N/A – Predictive pump analysis is verified at the system level and not represented by a discrete L3 behavior. | E73: This is verified through system testing, where the predictive maintenance algorithms are tested across a variety of operational conditions.
A74: ANGARS-73 | B74: Fuel Temperature Monitoring | C74: The system shall monitor fuel temperature within 2C (T), 1C (O) accuracy. | D74: N/A – Fuel temperature monitoring is part of the integrated sensor suite. | E74: This is confirmed through sensor calibration and overall system-level testing.
A75: ANGARS-74 | B75: Hydraulic Fault Speed | C75: The system shall identify and diagnose hydraulic system faults in ≤ 10 seconds (T), 5 seconds (O). | D75: N/A – Hydraulic fault detection is part of the overall diagnostic system. | E75: Verified during integrated testing where hydraulic system responses are monitored for speed and accuracy.
A76: ANGARS-75 | B76: Sensor Isolation | C76: The system shall isolate faulty sensors during diagnostics. | D76: F4.5: Sensor Isolation | E76: This behavior isolates faulty sensors to prevent them from impacting system diagnostics, ensuring accurate analysis and continued operation.
A77: ANGARS-76 | B77: Low Pressure Alert | C77: The system shall alert operators of low fuel pressure. | D77: F4.6: Send Status Notifications | E77: This behavior sends alerts to operators in real-time if fuel pressure falls below safe levels.
A78: ANGARS-77 | B78: Log Archive | C78: The system shall archive diagnostics logs for ≥ 1 year (T), 2 years (O). | D78: F4.3: Log Failures and Archive Data | E78: This activity ensures that diagnostic logs are stored for long-term retention, meeting the archival requirements.
A79: ANGARS-78 | B79: FAA Compliance | C79: The system shall comply with FAA airworthiness standards. | D79: N/A – Compliance with FAA standards is verified at the system design and regulatory compliance level, not via a specific L3 activity. | E79: Verified through system-level certification processes and regulatory review.
A80: ANGARS-79 | B80: MIL-STD-882E Compliance | C80: The system shall meet or exceed MIL-STD-882E safety protocols. | D80: N/A – Compliance is verified through safety audits and system reviews rather than by an individual L3 behavior. | E80: Achieved through formal safety assessments and certification procedures.
... A155: ANGARS-154 | B155: Mission Status Updates | C155: The system shall transmit mission status updates to ground control every 30 seconds. | D155: F1.6: Transmit Status & Reports | E155: This behavior ensures that mission status updates are sent periodically to maintain situational awareness for operators.

Sheet All Behaviors
A1: # | B1: ID | C1: Level | D1: Name | E1: Owner | F1: Requirements Satisfied
A2: 1 | C2: L1 | D2: ANGARS Top Level System Behaviors | E2: ANGARS Top Level
A3: 2 | B3: F1 | C3: L2 | D3: F1: Manage Refueling Requests | E3: ANGARS Top Level System Behaviors
A4: 3 | B4: F2 | C4: L2 | D4: F2: Control Autonomous Docking | E4: ANGARS Top Level System Behaviors
A5: 4 | B5: F3 | C5: L2 | D5: F3: Execute Fuel Transfer | E5: ANGARS Top Level System Behaviors
A6: 5 | B6: F4 | C6: L2 | D6: F4: Monitor Safety & Diagnostics | E6: ANGARS Top Level System Behaviors
A7: 6 | B7: F5 | C7: L2 | D7: F5: Manage Communications | E7: ANGARS Top Level System Behaviors
A8: 7 | B8: F6 | C8: L2 | D8: F6: Operate in Adverse Conditions | E8: ANGARS Top Level System Behaviors
A9: 8 | B9: F7 | C9: L2 | D9: F7: Enforce Cybersecurity | E9: ANGARS Top Level System Behaviors
A10: 9 | B10: F8 | C10: L2 | D10: F8: Manage HMI | E10: ANGARS Top Level System Behaviors
A11: 10 | B11: F1.1 | C11: L3 | D11: F1.1: Receive & Authenticate Request | E11: F1: Manage Refueling Requests
A12: 11 | B12: F1.2 | C12: L3 | D12: F1.2: Validate Fuel Capacity | E12: F1: Manage Refueling Requests
A13: 12 | B13: F1.3 | C13: L3 | D13: F1.3: Prioritize Requests | E13: F1: Manage Refueling Requests
A14: 13 | B14: F1.4 | C14: L3 | D14: F1.4: Generate Schedule | E14: F1: Manage Refueling Requests
... A64: 63 | B64: F8.9 | C64: L3 | D64: F8.9: Reprioritize Refueling Queue | E64: F8: Manage HMI

Sheet VLOOKUP
A2: ANGARS-1 | B2: F2: Control Autonomous Docking_THIS F3: Execute Fuel Transfer_THIS | C2: F2 (autonomous docking) and F3 (fuel transfer) enable refueling without human intervention. | D2: No
A3: ANGARS-2 | B3: None | C3: Refueling time is a performance metric not captured in functional flows. | D3: Yes
A4: ANGARS-3 | B4: F4: Monitor Safety & Diagnostics_THIS | C4: F4 monitors proximity and triggers safety abort via alerts to F2/F3. | D4: No
A5: ANGARS-4 | B5: F1: Manage Refueling Requests_THIS | C5: F1 verifies aircraft identity during refueling request processing. | D5: No
A6: ANGARS-5 | B6: F2: Control Autonomous Docking_THIS | C6: F2 stabilizes the connection during turbulence using guidance signals from F6. | D6: No
A7: ANGARS-6 | B7: F2: Control Autonomous Docking_THIS | C7: F2 aligns the probe within accuracy bounds using F6’s navigation signals. | D7: No
A8: ANGARS-7 | B8: F3: Execute Fuel Transfer_THIS F4: Monitor Safety & Diagnostics_THIS | C8: F3 detects leaks and stops transfer; F4 logs diagnostics. | D8: No
A9: ANGARS-8 | B9: F3: Execute Fuel Transfer_THIS | C9: F3 adjusts fuel speed based on stability data from F2. | D9: No
A10: ANGARS-9 | B10: F2: Control Autonomous Docking_THIS | C10: F2 retracts the probe after F3 confirms fuel transfer completion. | D10: No
A11: ANGARS-10 | B11: F1: Manage Refueling Requests_THIS | C11: F1 handles refueling requests for both manned and unmanned aircraft. | D11: No
A12: ANGARS-11 | B12: F2: Control Autonomous Docking_THIS | C12: F2 adjusts docking procedures for wingspan compatibility. | D12: No
A13: ANGARS-12 | B13: F3: Execute Fuel Transfer_THIS | C13: F3 adapts fuel flow rate based on aircraft type/properties. | D13: No
... A94: ANGARS-154 | B94: F1: Manage Refueling Requests_THIS | C94: F1 transmits mission status updates every 30 seconds. | D94: No

Sheet Sheet1
A1: F1: Manage Refueling Requests | B1: =A1&+"_THIS" -> F1: Manage Refueling Requests_THIS
A2: F2: Control Autonomous Docking | B2: =A2&+"_THIS" -> F2: Control Autonomous Docking_THIS
A3: F3: Execute Fuel Transfer | B3: =A3&+"_THIS" -> F3: Execute Fuel Transfer_THIS
A4: F4: Monitor Safety & Diagnostics | B4: =A4&+"_THIS" -> F4: Monitor Safety & Diagnostics_THIS
A5: F5: Manage Communications | B5: =A5&+"_THIS" -> F5: Manage Communications_THIS
A6: F6: Operate in Adverse Conditions | B6: =A6&+"_THIS" -> F6: Operate in Adverse Conditions_THIS
A7: F7: Enforce Cybersecurity | B7: =A7&+"_THIS" -> F7: Enforce Cybersecurity_THIS
A8: F8: Manage HMI | B8: =A8&+"_THIS" -> F8: Manage HMI_THIS
